Workbook

Sheet Dashboard
B1: Export Packing - Cost per Vessel and Outsourcing Check
B2: FRP pressure vessels 1.4-3.0 m | 19 export packing jobs, Oct-25 to Jul-26 | rates as of Aug-26
B3: Case study by Kousani Das | Sep-2026 | all data simulated for illustration - no company, customer or supplier data included (see Notes)
B5: SELECT | F5: KEY FINDINGS
B6: Vessel size (mm) | D6: 2400 | F6: ="1. Actual vs design: 2.0 m jobs used "&TEXT('Proposed Std'!D33/'Proposed Std'!C33-1,"0%")&" more timber than the BOM. The other 6 sizes had no BOM - standards proposed from "&COUNTIF('Job Costing'!B5:B23,"<>2000")&" jobs." -> 1. Actual vs design: 2.0 m jobs used 6% more timber than the BOM. The other 6 sizes had no BOM - standards proposed from 16 jobs.
B7: Vessels per shipment | D7: 4 | F7: ="2. Flat-rack sizes (2.4 m and above) cost "&TEXT(H11/E11,"0.0")&"x a container size to pack - heavier saddles and weather cover." -> 2. Flat-rack sizes (2.4 m and above) cost 2.0x a container size to pack - heavier saddles and weather cover.
F8: ="3. In-house is the cheapest way to pack every size; the turnkey packer quotes about "&TEXT(AVERAGE('Size Model'!E43:I43),"0.0")&"x our own cost." -> 3. In-house is the cheapest way to pack every size; the turnkey packer quotes about 1.2x our own cost.
F9: 4. Next step: release the proposed BOMs. Buy ready-made skids only if the packing bay becomes a bottleneck.
B10: Vessels packed | E10: Avg cost per vessel - container sizes | H10: Avg cost per vessel - flat-rack sizes | K10: Rupee move since USD price set | N10: Cheapest for selected size
B11: =SUM('Job Costing'!C5:C23) -> 60 | E11: =SUMIFS('Job Costing'!X5:X23,'Job Costing'!E5:E23,"40HC")/SUMIFS('Job Costing'!C5:C23,'Job Costing'!E5:E23,"40HC") -> 13125.772 | H11: =SUMIFS('Job Costing'!X5:X23,'Job Costing'!E5:E23,"Flat rack")/SUMIFS('Job Costing'!C5:C23,'Job Costing'!E5:E23,"Flat rack") -> 26353.187 | K11: =Inputs!$C$88/Inputs!$C$87-1 -> 0.094010268 | N11: =HLOOKUP(D6,'Size Model'!C4:I41,38,0) -> In-house
B12: =COUNTA('Job Costing'!A5:A23)&" jobs" -> 19 jobs | E12: ="1.4-2.0 m" -> 1.4-2.0 m | H12: ="2.4-3.0 m" -> 2.4-3.0 m | K12: ="USD-INR "&TEXT(Inputs!$C$87,"0.00")&" to "&TEXT(Inputs!$C$88,"0.00") -> USD-INR 87.65 to 95.89 | N12: ="at "&D7&" vessels per shipment" -> at 4 vessels per shipment
B46: Terms
B47: • Flat rack: open container frame for vessels too wide for a closed container door
B48: • 40HC: 40-ft high-cube container. Skid / saddle: timber base the vessel lies on
B49: • PK-A / PK-B / PK-C: contractor labour only / buy ready-made skids / turnkey packer
B50: • Packing-bay day: one day of the packing area being used. Mistri / jogali: carpenter / helper

Sheet Notes
A1: Notes - what this workbook does
A3: Goal | B3: Management asked for two things: close the gap between actual and design BOMs, and decide which outsourced activities should be done in-house. Export packing had a written BOM for only one vessel size (2.0 m); every other size was packed as the supervisor decided. This workbook costs the past packing jobs, proposes a standard BOM for the 6 sizes without one, and compares in-house packing with three outsourcing options.
A4: Roles | B4: Engineering inputs (packing method, vessel dimensions, what a BOM should contain) came from the project engineer. Data collection, cleaning, the costing model, the analysis and the dashboard are my work.
A5: Data | B5: Fictional case study. All data - orders, SAP stores issues, labour log, BOM, vendor quotes - is simulated to mirror the structure of real SAP exports and shop records. No company, customer or supplier data is included. Material rates, wages and USD-INR are anchored to public market data (links at the bottom of Data - Rates).
A6: Steps | B6: 1) Pasted the SAP export and logs (Data tabs). 2) Added check columns: corrected job, size, rate item, timber cft, fixed dates and hours, rate conversions. 3) Costed each job (Job Costing). 4) Averaged use per vessel by size = proposed standard (Proposed Std). 5) Compared in-house with 3 outsourcing options (Size Model, Outsourcing). 6) Dashboard.
A7: Data issues fixed | B7: 2 SAP lines posted to the wrong job and 1 job with Ref2 blank (job taken from comments); 3 dates typed as text; 1 day of hours not noted (8 hrs taken); timber quoted once per CBM, tape per box of 12; 1 rate including GST; 1 typo (Rs 1,660/kg should be 166); 27 vendor item names mapped to 13 items.
A8: Assumptions | B8: Design pressure 7.5-10 bar (wall thickness at the upper end - a few mm, no effect on packing cost). Jobs before Feb-26 have no labour record: labour = average hours per vessel of logged jobs of the same size. OT paid at double rate. Supervision + marking Rs 1,025 per shipment. Crews: 24 man-hrs/day in-house, 40 for PK-C. Billed packaging price is an illustrative index. All assumptions are on the Inputs tab.
A9: Limitations | B9: Small sample - 19 jobs, 1 to 5 per size. Proposed standards are averages and need production sign-off. Flat-rack lashing not checked against sea-transport forces. Vendor quotes are estimates built from market rates.
A10: Terms | B10: Flat rack = open container frame for over-width cargo. 40HC = 40-ft high-cube container. Skid / saddle = timber base. Packing-bay day = one day of the packing area in use. Mistri / jogali = carpenter / helper. PK-A / PK-B / PK-C = contractor labour only / buy ready-made skids / turnkey packer.

Sheet Inputs
A1: Inputs
A2: Blue on green = typed by me. Black = linked. Change assumptions here only.
A4: 1. Current rates (latest valid line in Data - Rates)
A5: Item | B5: UoM | C5: Rate ₹ | D5: As of | E5: Rates row
A6: Timber | B6: cft | C6: ='Data - Rates'!M35 -> 780 | D6: ='Data - Rates'!A35 -> 46253 | E6: 35
A7: Nails | B7: set | C7: ='Data - Rates'!M26 -> 99 | D7: ='Data - Rates'!A26 -> 46183 | E7: 26
A8: Foam | B8: roll | C8: ='Data - Rates'!M31 -> 2250 | D8: ='Data - Rates'!A31 -> 46211 | E8: 31
A9: Ratchet belt | B9: nos | C9: ='Data - Rates'!M29 -> 950 | D9: ='Data - Rates'!A29 -> 46211 | E9: 29
A10: Gum tape | B10: roll | C10: ='Data - Rates'!M32 -> 84 | D10: ='Data - Rates'!A32 -> 46211 | E10: 32
A11: Stretch film | B11: kg | C11: ='Data - Rates'!M30 -> 167.79661 | D11: ='Data - Rates'!A30 -> 46211 | E11: 30
A12: Bubble wrap | B12: roll | C12: ='Data - Rates'!M34 -> 710 | D12: ='Data - Rates'!A34 -> 46238 | E12: 34
A13: Ply cover | B13: nos | C13: ='Data - Rates'!M14 -> 160 | D13: ='Data - Rates'!A14 -> 45915 | E13: 14
A14: Tarpaulin | B14: sqft | C14: ='Data - Rates'!M15 -> 5 | D14: ='Data - Rates'!A15 -> 45915 | E14: 15
A15: Fumigation | B15: per 40HC | C15: ='Data - Rates'!M33 -> 3500 | D15: ='Data - Rates'!A33 -> 46213 | E15: 33
A16: Carpenter | B16: day | C16: ='Data - Rates'!M24 -> 800 | D16: ='Data - Rates'!A24 -> 46113 | E16: 24
A17: Helper | B17: day | C17: ='Data - Rates'!M28 -> 480 | D17: ='Data - Rates'!A28 -> 46204 | E17: 28
A19: 2. Labour and other assumptions
A20: Contractor margin on labour | C20: 0.1 | D20: labour contractor bill
A21: Working hours per day | C21: 8 | D21: WB: 8.5 hr day incl. 0.5 hr rest
A22: Supervision + marking per shipment ₹ | C22: 1025 | D22: 0.5 day supervisor (~₹425) + stencil/labels/photos ₹600
A23: Our packing crew (man-hrs per day) | C23: 24 | D23: 1 mistri + 2 jogali x 8 hrs
A24: PK-C crew (man-hrs per day) | C24: 40 | D24: assumed 5-man crew
A25: PK-B skid sets per tempo trip | C25: 3 | D25: assumed
A26: Value of a free packing-bay day ₹ | C26: 0 | D26: 0 = ignore. Set >0 if the packing bay is a bottleneck
A28: 3. Wage history (from Data - Rates) - used by job date
A29: From date | B29: Carpenter ₹/day | C29: Helper ₹/day
A30: 45870 | B30: 760 | C30: 460
A31: 46113 | B31: 800 | C31: 460
A32: 46204 | B32: 800 | C32: 480
A34: 4. Fumigation rate history (per 40HC container)
A35: From date | B35: ₹ per container
A36: 45910 | B36: 3000
A37: 46050 | B37: 3200
A38: 46213 | B38: 3500
A39: 5. Outsourcing quotes per vessel (from quote e-mails, Aug-Sep 26)
A40: Size (mm) | B40: PK-A labour only | C40: PK-B skid set | D40: PK-C turnkey
A41: 1400 | B41: 800 | C41: 6400 | D41: NQ = not quoted (PK-C does not take jobs below 1.8 m)
A42: 1600 | B42: 900 | C42: 6850 | D42: NQ
A43: 1800 | B43: 1100 | C43: 7350 | D43: 15000
A44: 2000 | B44: 1000 | C44: 7200 | D44: 14000
...

Sheet Job Costing
A1: Job costing - packing cost per job (actuals)
A2: Blue = typed from SAP sales orders / GR docs. Jobs before Feb-26 have no labour record - average hrs per vessel of the same size used.
A4: Job no. | B4: Size (mm) | C4: Vessels | D4: Packed on | E4: Ship mode | F4: Timber ₹ | G4: Consumables ₹ | H4: Returns ₹ | I4: Material ₹ | J4: Mistri hrs (log) | K4: Jogali hrs (log) | L4: Labour record? | M4: Mistri hrs / vsl | N4: Jogali hrs / vsl | O4: Mistri hrs used | P4: Jogali hrs used | Q4: Carpenter ₹/day | R4: Helper ₹/day | S4: Labour ₹ | T4: OT hrs | U4: OT extra ₹ | V4: Fumigation ₹ | W4: Supervision ₹ | X4: Total ₹ | Y4: ₹ per vessel | Z4: USD-INR | AA4: USD per vessel | AB4: Timber cft issued | AC4: Notes
A5: J/25-26/135 | B5: 2600 | C5: 3 | D5: 45939 | E5: =VLOOKUP(B5,Inputs!$A$54:$L$60,11,0) -> Flat rack | F5: =SUMIFS('Data - SAP Issues'!$I$4:$I$254,'Data - SAP Issues'!$K$4:$K$254,A5,'Data - SAP Issues'!$M$4:$M$254,"Timber") -> 31538.33 | G5: =SUMIFS('Data - SAP Issues'!$I$4:$I$254,'Data - SAP Issues'!$K$4:$K$254,A5)-F5 -> 33544.2 | H5: 0 | I5: =F5+G5-H5 -> 65082.53 | J5: =SUMIFS('Data - Labour'!$M$5:$M$92,'Data - Labour'!$G$5:$G$92,A5,'Data - Labour'!$B$5:$B$92,"Mistri") -> 0 | K5: =SUMIFS('Data - Labour'!$M$5:$M$92,'Data - Labour'!$G$5:$G$92,A5,'Data - Labour'!$B$5:$B$92,"Jogali") -> 0 | L5: =IF(J5+K5>0,"Yes","No") -> No | M5: =IF(L5="Yes",J5/C5,"") | N5: =IF(L5="Yes",K5/C5,"") | O5: =IF(L5="Yes",J5,AVERAGEIFS($M$5:$M$23,$B$5:$B$23,B5)*C5) -> 26.625 | P5: =IF(L5="Yes",K5,AVERAGEIFS($N$5:$N$23,$B$5:$B$23,B5)*C5) -> 61.5625 | Q5: =VLOOKUP(D5,Inputs!$A$30:$C$32,2,TRUE()) -> 760 | R5: =VLOOKUP(D5,Inputs!$A$30:$C$32,3,TRUE()) -> 460 | S5: =(O5*Q5+P5*R5)/Inputs!$C$21*(1+Inputs!$C$20) -> 6676.1406 | T5: =SUMIFS('Data - Labour'!$N$5:$N$92,'Data - Labour'!$G$5:$G$92,A5) -> 0 | U5: =T5*(Q5+R5)/2/Inputs!$C$21*(1+Inputs!$C$20) -> 0 | V5: =IF(E5="40HC",ROUNDUP(C5/VLOOKUP(B5,Inputs!$A$54:$L$60,12,0),0)*VLOOKUP(D5,Inputs!$A$36:$B$38,2,TRUE()),0) -> 0 | W5: =Inputs!$C$22 -> 1025 | X5: =I5+S5+U5+V5+W5 -> 72783.671 | Y5: =X5/C5 -> 24261.224 | Z5: =VLOOKUP(D5,Inputs!$A$66:$B$85,2,TRUE()) -> 88.26 | AA5: =Y5/Z5 -> 274.88357 | AB5: =SUMIFS('Data - SAP Issues'!$N$4:$N$254,'Data - SAP Issues'!$K$4:$K$254,A5) -> 45.048939 | AC5: no labour record (before Feb-26)
A6: J/25-26/118 | B6: 2400 | C6: 2 | D6: 45951 | E6: =VLOOKUP(B6,Inputs!$A$54:$L$60,11,0) -> Flat rack | F6: =SUMIFS('Data - SAP Issues'!$I$4:$I$254,'Data - SAP Issues'!$K$4:$K$254,A6,'Data - SAP Issues'!$M$4:$M$254,"Timber") -> 20415.81 | G6: =SUMIFS('Data - SAP Issues'!$I$4:$I$254,'Data - SAP Issues'!$K$4:$K$254,A6)-F6 -> 22543.6 | H6: 0 | I6: =F6+G6-H6 -> 42959.41 | J6: =SUMIFS('Data - Labour'!$M$5:$M$92,'Data - Labour'!$G$5:$G$92,A6,'Data - Labour'!$B$5:$B$92,"Mistri") -> 0 | K6: =SUMIFS('Data - Labour'!$M$5:$M$92,'Data - Labour'!$G$5:$G$92,A6,'Data - Labour'!$B$5:$B$92,"Jogali") -> 0 | L6: =IF(J6+K6>0,"Yes","No") -> No | M6: =IF(L6="Yes",J6/C6,"") | N6: =IF(L6="Yes",K6/C6,"") | O6: =IF(L6="Yes",J6,AVERAGEIFS($M$5:$M$23,$B$5:$B$23,B6)*C6) -> 19.633333 | P6: =IF(L6="Yes",K6,AVERAGEIFS($N$5:$N$23,$B$5:$B$23,B6)*C6) -> 37.9 | Q6: =VLOOKUP(D6,Inputs!$A$30:$C$32,2,TRUE()) -> 760 | R6: =VLOOKUP(D6,Inputs!$A$30:$C$32,3,TRUE()) -> 460 | S6: =(O6*Q6+P6*R6)/Inputs!$C$21*(1+Inputs!$C$20) -> 4448.8583 | T6: =SUMIFS('Data - Labour'!$N$5:$N$92,'Data - Labour'!$G$5:$G$92,A6) -> 0 | U6: =T6*(Q6+R6)/2/Inputs!$C$21*(1+Inputs!$C$20) -> 0 | V6: =IF(E6="40HC",ROUNDUP(C6/VLOOKUP(B6,Inputs!$A$54:$L$60,12,0),0)*VLOOKUP(D6,Inputs!$A$36:$B$38,2,TRUE()),0) -> 0 | W6: =Inputs!$C$22 -> 1025 | X6: =I6+S6+U6+V6+W6 -> 48433.268 | Y6: =X6/C6 -> 24216.634 | Z6: =VLOOKUP(D6,Inputs!$A$66:$B$85,2,TRUE()) -> 87.82 | AA6: =Y6/Z6 -> 275.75306 | AB6: =SUMIFS('Data - SAP Issues'!$N$4:$N$254,'Data - SAP Issues'!$K$4:$K$254,A6) -> 29.161646 | AC6: no labour record (before Feb-26)
A7: J/25-26/120 | B7: 1800 | C7: 4 | D7: 45967 | E7: =VLOOKUP(B7,Inputs!$A$54:$L$60,11,0) -> 40HC | F7: =SUMIFS('Data - SAP Issues'!$I$4:$I$254,'Data - SAP Issues'!$K$4:$K$254,A7,'Data - SAP Issues'!$M$4:$M$254,"Timber") -> 21654.84 | G7: =SUMIFS('Data - SAP Issues'!$I$4:$I$254,'Data - SAP Issues'!$K$4:$K$254,A7)-F7 -> 20153 | H7: 0 | I7: =F7+G7-H7 -> 41807.84 | J7: =SUMIFS('Data - Labour'!$M$5:$M$92,'Data - Labour'!$G$5:$G$92,A7,'Data - Labour'!$B$5:$B$92,"Mistri") -> 0 | K7: =SUMIFS('Data - Labour'!$M$5:$M$92,'Data - Labour'!$G$5:$G$92,A7,'Data - Labour'!$B$5:$B$92,"Jogali") -> 0 | L7: =IF(J7+K7>0,"Yes","No") -> No | M7: =IF(L7="Yes",J7/C7,"") | N7: =IF(L7="Yes",K7/C7,"") | O7: =IF(L7="Yes",J7,AVERAGEIFS($M$5:$M$23,$B$5:$B$23,B7)*C7) -> 19 | P7: =IF(L7="Yes",K7,AVERAGEIFS($N$5:$N$23,$B$5:$B$23,B7)*C7) -> 40.5 | Q7: =VLOOKUP(D7,Inputs!$A$30:$C$32,2,TRUE()) -> 760 | R7: =VLOOKUP(D7,Inputs!$A$30:$C$32,3,TRUE()) -> 460 | S7: =(O7*Q7+P7*R7)/Inputs!$C$21*(1+Inputs!$C$20) -> 4547.125 | T7: =SUMIFS('Data - Labour'!$N$5:$N$92,'Data - Labour'!$G$5:$G$92,A7) -> 0 | U7: =T7*(Q7+R7)/2/Inputs!$C$21*(1+Inputs!$C$20) -> 0 | V7: =IF(E7="40HC",ROUNDUP(C7/VLOOKUP(B7,Inputs!$A$54:$L$60,12,0),0)*VLOOKUP(D7,Inputs!$A$36:$B$38,2,TRUE()),0) -> 6000 | W7: =Inputs!$C$22 -> 1025 | X7: =I7+S7+U7+V7+W7 -> 53379.965 | Y7: =X7/C7 -> 13344.991 | Z7: =VLOOKUP(D7,Inputs!$A$66:$B$85,2,TRUE()) -> 88.7 | AA7: =Y7/Z7 -> 150.45086 | AB7: =SUMIFS('Data - SAP Issues'!$N$4:$N$254,'Data - SAP Issues'!$K$4:$K$254,A7) -> 30.93156 | AC7: no labour record (before Feb-26)
A8: J/25-26/122 | B8: 2600 | C8: 2 | D8: 45979 | E8: =VLOOKUP(B8,Inputs!$A$54:$L$60,11,0) -> Flat rack | F8: =SUMIFS('Data - SAP Issues'!$I$4:$I$254,'Data - SAP Issues'!$K$4:$K$254,A8,'Data - SAP Issues'!$M$4:$M$254,"Timber") -> 25860.44 | G8: =SUMIFS('Data - SAP Issues'!$I$4:$I$254,'Data - SAP Issues'!$K$4:$K$254,A8)-F8 -> 24937.8 | H8: 0 | I8: =F8+G8-H8 -> 50798.24 | J8: =SUMIFS('Data - Labour'!$M$5:$M$92,'Data - Labour'!$G$5:$G$92,A8,'Data - Labour'!$B$5:$B$92,"Mistri") -> 0 | K8: =SUMIFS('Data - Labour'!$M$5:$M$92,'Data - Labour'!$G$5:$G$92,A8,'Data - Labour'!$B$5:$B$92,"Jogali") -> 0 | L8: =IF(J8+K8>0,"Yes","No") -> No | M8: =IF(L8="Yes",J8/C8,"") | N8: =IF(L8="Yes",K8/C8,"") | O8: =IF(L8="Yes",J8,AVERAGEIFS($M$5:$M$23,$B$5:$B$23,B8)*C8) -> 17.75 | P8: =IF(L8="Yes",K8,AVERAGEIFS($N$5:$N$23,$B$5:$B$23,B8)*C8) -> 41.041667 | Q8: =VLOOKUP(D8,Inputs!$A$30:$C$32,2,TRUE()) -> 760 | R8: =VLOOKUP(D8,Inputs!$A$30:$C$32,3,TRUE()) -> 460 | S8: =(O8*Q8+P8*R8)/Inputs!$C$21*(1+Inputs!$C$20) -> 4450.7604 | T8: =SUMIFS('Data - Labour'!$N$5:$N$92,'Data - Labour'!$G$5:$G$92,A8) -> 0 | U8: =T8*(Q8+R8)/2/Inputs!$C$21*(1+Inputs!$C$20) -> 0 | V8: =IF(E8="40HC",ROUNDUP(C8/VLOOKUP(B8,Inputs!$A$54:$L$60,12,0),0)*VLOOKUP(D8,Inputs!$A$36:$B$38,2,TRUE()),0) -> 0 | W8: =Inputs!$C$22 -> 1025 | X8: =I8+S8+U8+V8+W8 -> 56274 | Y8: =X8/C8 -> 28137 | Z8: =VLOOKUP(D8,Inputs!$A$66:$B$85,2,TRUE()) -> 88.66 | AA8: =Y8/Z8 -> 317.35845 | AB8: =SUMIFS('Data - SAP Issues'!$N$4:$N$254,'Data - SAP Issues'!$K$4:$K$254,A8) -> 36.938674 | AC8: no labour record (before Feb-26); 3 battens split - addl issue
A9: J/25-26/124 | B9: 2400 | C9: 4 | D9: 45988 | E9: =VLOOKUP(B9,Inputs!$A$54:$L$60,11,0) -> Flat rack | F9: =SUMIFS('Data - SAP Issues'!$I$4:$I$254,'Data - SAP Issues'!$K$4:$K$254,A9,'Data - SAP Issues'!$M$4:$M$254,"Timber") -> 42075.3 | G9: =SUMIFS('Data - SAP Issues'!$I$4:$I$254,'Data - SAP Issues'!$K$4:$K$254,A9)-F9 -> 42876.8 | H9: 0 | I9: =F9+G9-H9 -> 84952.1 | J9: =SUMIFS('Data - Labour'!$M$5:$M$92,'Data - Labour'!$G$5:$G$92,A9,'Data - Labour'!$B$5:$B$92,"Mistri") -> 0 | K9: =SUMIFS('Data - Labour'!$M$5:$M$92,'Data - Labour'!$G$5:$G$92,A9,'Data - Labour'!$B$5:$B$92,"Jogali") -> 0 | L9: =IF(J9+K9>0,"Yes","No") -> No | M9: =IF(L9="Yes",J9/C9,"") | N9: =IF(L9="Yes",K9/C9,"") | O9: =IF(L9="Yes",J9,AVERAGEIFS($M$5:$M$23,$B$5:$B$23,B9)*C9) -> 39.266667 | P9: =IF(L9="Yes",K9,AVERAGEIFS($N$5:$N$23,$B$5:$B$23,B9)*C9) -> 75.8 | Q9: =VLOOKUP(D9,Inputs!$A$30:$C$32,2,TRUE()) -> 760 | R9: =VLOOKUP(D9,Inputs!$A$30:$C$32,3,TRUE()) -> 460 | S9: =(O9*Q9+P9*R9)/Inputs!$C$21*(1+Inputs!$C$20) -> 8897.7167 | T9: =SUMIFS('Data - Labour'!$N$5:$N$92,'Data - Labour'!$G$5:$G$92,A9) -> 0 | U9: =T9*(Q9+R9)/2/Inputs!$C$21*(1+Inputs!$C$20) -> 0 | V9: =IF(E9="40HC",ROUNDUP(C9/VLOOKUP(B9,Inputs!$A$54:$L$60,12,0),0)*VLOOKUP(D9,Inputs!$A$36:$B$38,2,TRUE()),0) -> 0 | W9: =Inputs!$C$22 -> 1025 | X9: =I9+S9+U9+V9+W9 -> 94874.817 | Y9: =X9/C9 -> 23718.704 | Z9: =VLOOKUP(D9,Inputs!$A$66:$B$85,2,TRUE()) -> 88.66 | AA9: =Y9/Z9 -> 267.5243 | AB9: =SUMIFS('Data - SAP Issues'!$N$4:$N$254,'Data - SAP Issues'!$K$4:$K$254,A9) -> 60.099827 | AC9: no labour record (before Feb-26)
A10: J/25-26/130 | B10: 1400 | C10: 2 | D10: 46001 | E10: =VLOOKUP(B10,Inputs!$A$54:$L$60,11,0) -> 40HC | F10: =SUMIFS('Data - SAP Issues'!$I$4:$I$254,'Data - SAP Issues'!$K$4:$K$254,A10,'Data - SAP Issues'!$M$4:$M$254,"Timber") -> 12445.02 | G10: =SUMIFS('Data - SAP Issues'!$I$4:$I$254,'Data - SAP Issues'!$K$4:$K$254,A10)-F10 -> 9453.2 | H10: 0 | I10: =F10+G10-H10 -> 21898.22 | J10: =SUMIFS('Data - Labour'!$M$5:$M$92,'Data - Labour'!$G$5:$G$92,A10,'Data - Labour'!$B$5:$B$92,"Mistri") -> 0 | K10: =SUMIFS('Data - Labour'!$M$5:$M$92,'Data - Labour'!$G$5:$G$92,A10,'Data - Labour'!$B$5:$B$92,"Jogali") -> 0 | L10: =IF(J10+K10>0,"Yes","No") -> No | M10: =IF(L10="Yes",J10/C10,"") | N10: =IF(L10="Yes",K10/C10,"") | O10: =IF(L10="Yes",J10,AVERAGEIFS($M$5:$M$23,$B$5:$B$23,B10)*C10) -> 7 | P10: =IF(L10="Yes",K10,AVERAGEIFS($N$5:$N$23,$B$5:$B$23,B10)*C10) -> 17.666667 | Q10: =VLOOKUP(D10,Inputs!$A$30:$C$32,2,TRUE()) -> 760 | R10: =VLOOKUP(D10,Inputs!$A$30:$C$32,3,TRUE()) -> 460 | S10: =(O10*Q10+P10*R10)/Inputs!$C$21*(1+Inputs!$C$20) -> 1848.9167 | T10: =SUMIFS('Data - Labour'!$N$5:$N$92,'Data - Labour'!$G$5:$G$92,A10) -> 0 | U10: =T10*(Q10+R10)/2/Inputs!$C$21*(1+Inputs!$C$20) -> 0 | V10: =IF(E10="40HC",ROUNDUP(C10/VLOOKUP(B10,Inputs!$A$54:$L$60,12,0),0)*VLOOKUP(D10,Inputs!$A$36:$B$38,2,TRUE()),0) -> 3000 | W10: =Inputs!$C$22 -> 1025 | X10: =I10+S10+U10+V10+W10 -> 27772.137 | Y10: =X10/C10 -> 13886.068 | Z10: =VLOOKUP(D10,Inputs!$A$66:$B$85,2,TRUE()) -> 89.53 | AA10: =Y10/Z10 -> 155.09961 | AB10: =SUMIFS('Data - SAP Issues'!$N$4:$N$254,'Data - SAP Issues'!$K$4:$K$254,A10) -> 17.776378 | AC10: no labour record (before Feb-26)
A11: J/25-26/134 | B11: 2000 | C11: 3 | D11: 46010 | E11: =VLOOKUP(B11,Inputs!$A$54:$L$60,11,0) -> 40HC | F11: =SUMIFS('Data - SAP Issues'!$I$4:$I$254,'Data - SAP Issues'!$K$4:$K$254,A11,'Data - SAP Issues'!$M$4:$M$254,"Timber") -> 17821.64 | G11: =SUMIFS('Data - SAP Issues'!$I$4:$I$254,'Data - SAP Issues'!$K$4:$K$254,A11)-F11 -> 15529.4 | H11: 0 | I11: =F11+G11-H11 -> 33351.04 | J11: =SUMIFS('Data - Labour'!$M$5:$M$92,'Data - Labour'!$G$5:$G$92,A11,'Data - Labour'!$B$5:$B$92,"Mistri") -> 0 | K11: =SUMIFS('Data - Labour'!$M$5:$M$92,'Data - Labour'!$G$5:$G$92,A11,'Data - Labour'!$B$5:$B$92,"Jogali") -> 0 | L11: =IF(J11+K11>0,"Yes","No") -> No | M11: =IF(L11="Yes",J11/C11,"") | N11: =IF(L11="Yes",K11/C11,"") | O11: =IF(L11="Yes",J11,AVERAGEIFS($M$5:$M$23,$B$5:$B$23,B11)*C11) -> 11.25 | P11: =IF(L11="Yes",K11,AVERAGEIFS($N$5:$N$23,$B$5:$B$23,B11)*C11) -> 28.55 | Q11: =VLOOKUP(D11,Inputs!$A$30:$C$32,2,TRUE()) -> 760 | R11: =VLOOKUP(D11,Inputs!$A$30:$C$32,3,TRUE()) -> 460 | S11: =(O11*Q11+P11*R11)/Inputs!$C$21*(1+Inputs!$C$20) -> 2981.4125 | T11: =SUMIFS('Data - Labour'!$N$5:$N$92,'Data - Labour'!$G$5:$G$92,A11) -> 0 | U11: =T11*(Q11+R11)/2/Inputs!$C$21*(1+Inputs!$C$20) -> 0 | V11: =IF(E11="40HC",ROUNDUP(C11/VLOOKUP(B11,Inputs!$A$54:$L$60,12,0),0)*VLOOKUP(D11,Inputs!$A$36:$B$38,2,TRUE()),0) -> 3000 | W11: =Inputs!$C$22 -> 1025 | X11: =I11+S11+U11+V11+W11 -> 40357.452 | Y11: =X11/C11 -> 13452.484 | Z11: =VLOOKUP(D11,Inputs!$A$66:$B$85,2,TRUE()) -> 89.53 | AA11: =Y11/Z11 -> 150.25672 | AB11: =SUMIFS('Data - SAP Issues'!$N$4:$N$254,'Data - SAP Issues'!$K$4:$K$254,A11) -> 25.456303 | AC11: released BOM (first packing BOM)
A12: J/25-26/139 | B12: 1600 | C12: 2 | D12: 46065 | E12: =VLOOKUP(B12,Inputs!$A$54:$L$60,11,0) -> 40HC | F12: =SUMIFS('Data - SAP Issues'!$I$4:$I$254,'Data - SAP Issues'!$K$4:$K$254,A12,'Data - SAP Issues'!$M$4:$M$254,"Timber") -> 12052.21 | G12: =SUMIFS('Data - SAP Issues'!$I$4:$I$254,'Data - SAP Issues'!$K$4:$K$254,A12)-F12 -> 10024.6 | H12: 0 | I12: =F12+G12-H12 -> 22076.81 | J12: =SUMIFS('Data - Labour'!$M$5:$M$92,'Data - Labour'!$G$5:$G$92,A12,'Data - Labour'!$B$5:$B$92,"Mistri") -> 8.5 | K12: =SUMIFS('Data - Labour'!$M$5:$M$92,'Data - Labour'!$G$5:$G$92,A12,'Data - Labour'!$B$5:$B$92,"Jogali") -> 18.5 | L12: =IF(J12+K12>0,"Yes","No") -> Yes | M12: =IF(L12="Yes",J12/C12,"") -> 4.25 | N12: =IF(L12="Yes",K12/C12,"") -> 9.25 | O12: =IF(L12="Yes",J12,AVERAGEIFS($M$5:$M$23,$B$5:$B$23,B12)*C12) -> 8.5 | P12: =IF(L12="Yes",K12,AVERAGEIFS($N$5:$N$23,$B$5:$B$23,B12)*C12) -> 18.5 | Q12: =VLOOKUP(D12,Inputs!$A$30:$C$32,2,TRUE()) -> 760 | R12: =VLOOKUP(D12,Inputs!$A$30:$C$32,3,TRUE()) -> 460 | S12: =(O12*Q12+P12*R12)/Inputs!$C$21*(1+Inputs!$C$20) -> 2058.375 | T12: =SUMIFS('Data - Labour'!$N$5:$N$92,'Data - Labour'!$G$5:$G$92,A12) -> 1 | U12: =T12*(Q12+R12)/2/Inputs!$C$21*(1+Inputs!$C$20) -> 83.875 | V12: =IF(E12="40HC",ROUNDUP(C12/VLOOKUP(B12,Inputs!$A$54:$L$60,12,0),0)*VLOOKUP(D12,Inputs!$A$36:$B$38,2,TRUE()),0) -> 3200 | W12: =Inputs!$C$22 -> 1025 | X12: =I12+S12+U12+V12+W12 -> 28444.06 | Y12: =X12/C12 -> 14222.03 | Z12: =VLOOKUP(D12,Inputs!$A$66:$B$85,2,TRUE()) -> 89.88 | AA12: =Y12/Z12 -> 158.23353 | AB12: =SUMIFS('Data - SAP Issues'!$N$4:$N$254,'Data - SAP Issues'!$K$4:$K$254,A12) -> 16.73694
A13: J/25-26/143 | B13: 1800 | C13: 2 | D13: 46072 | E13: =VLOOKUP(B13,Inputs!$A$54:$L$60,11,0) -> 40HC | F13: =SUMIFS('Data - SAP Issues'!$I$4:$I$254,'Data - SAP Issues'!$K$4:$K$254,A13,'Data - SAP Issues'!$M$4:$M$254,"Timber") -> 10478.98 | G13: =SUMIFS('Data - SAP Issues'!$I$4:$I$254,'Data - SAP Issues'!$K$4:$K$254,A13)-F13 -> 10438.2 | H13: 0 | I13: =F13+G13-H13 -> 20917.18 | J13: =SUMIFS('Data - Labour'!$M$5:$M$92,'Data - Labour'!$G$5:$G$92,A13,'Data - Labour'!$B$5:$B$92,"Mistri") -> 11 | K13: =SUMIFS('Data - Labour'!$M$5:$M$92,'Data - Labour'!$G$5:$G$92,A13,'Data - Labour'!$B$5:$B$92,"Jogali") -> 20.5 | L13: =IF(J13+K13>0,"Yes","No") -> Yes | M13: =IF(L13="Yes",J13/C13,"") -> 5.5 | N13: =IF(L13="Yes",K13/C13,"") -> 10.25 | O13: =IF(L13="Yes",J13,AVERAGEIFS($M$5:$M$23,$B$5:$B$23,B13)*C13) -> 11 | P13: =IF(L13="Yes",K13,AVERAGEIFS($N$5:$N$23,$B$5:$B$23,B13)*C13) -> 20.5 | Q13: =VLOOKUP(D13,Inputs!$A$30:$C$32,2,TRUE()) -> 760 | R13: =VLOOKUP(D13,Inputs!$A$30:$C$32,3,TRUE()) -> 460 | S13: =(O13*Q13+P13*R13)/Inputs!$C$21*(1+Inputs!$C$20) -> 2446.125 | T13: =SUMIFS('Data - Labour'!$N$5:$N$92,'Data - Labour'!$G$5:$G$92,A13) -> 0 | U13: =T13*(Q13+R13)/2/Inputs!$C$21*(1+Inputs!$C$20) -> 0 | V13: =IF(E13="40HC",ROUNDUP(C13/VLOOKUP(B13,Inputs!$A$54:$L$60,12,0),0)*VLOOKUP(D13,Inputs!$A$36:$B$38,2,TRUE()),0) -> 3200 | W13: =Inputs!$C$22 -> 1025 | X13: =I13+S13+U13+V13+W13 -> 27588.305 | Y13: =X13/C13 -> 13794.153 | Z13: =VLOOKUP(D13,Inputs!$A$66:$B$85,2,TRUE()) -> 89.88 | AA13: =Y13/Z13 -> 153.47299 | AB13: =SUMIFS('Data - SAP Issues'!$N$4:$N$254,'Data - SAP Issues'!$K$4:$K$254,A13) -> 14.552134
A14: J/25-26/145 | B14: 2400 | C14: 5 | D14: 46086 | E14: =VLOOKUP(B14,Inputs!$A$54:$L$60,11,0) -> Flat rack | F14: =SUMIFS('Data - SAP Issues'!$I$4:$I$254,'Data - SAP Issues'!$K$4:$K$254,A14,'Data - SAP Issues'!$M$4:$M$254,"Timber") -> 62918.17 | G14: =SUMIFS('Data - SAP Issues'!$I$4:$I$254,'Data - SAP Issues'!$K$4:$K$254,A14)-F14 -> 48229.4 | H14: 1128.8 | I14: =F14+G14-H14 -> 110018.77 | J14: =SUMIFS('Data - Labour'!$M$5:$M$92,'Data - Labour'!$G$5:$G$92,A14,'Data - Labour'!$B$5:$B$92,"Mistri") -> 46.5 | K14: =SUMIFS('Data - Labour'!$M$5:$M$92,'Data - Labour'!$G$5:$G$92,A14,'Data - Labour'!$B$5:$B$92,"Jogali") -> 92 | L14: =IF(J14+K14>0,"Yes","No") -> Yes | M14: =IF(L14="Yes",J14/C14,"") -> 9.3 | N14: =IF(L14="Yes",K14/C14,"") -> 18.4 | O14: =IF(L14="Yes",J14,AVERAGEIFS($M$5:$M$23,$B$5:$B$23,B14)*C14) -> 46.5 | P14: =IF(L14="Yes",K14,AVERAGEIFS($N$5:$N$23,$B$5:$B$23,B14)*C14) -> 92 | Q14: =VLOOKUP(D14,Inputs!$A$30:$C$32,2,TRUE()) -> 760 | R14: =VLOOKUP(D14,Inputs!$A$30:$C$32,3,TRUE()) -> 460 | S14: =(O14*Q14+P14*R14)/Inputs!$C$21*(1+Inputs!$C$20) -> 10678.25 | T14: =SUMIFS('Data - Labour'!$N$5:$N$92,'Data - Labour'!$G$5:$G$92,A14) -> 12 | U14: =T14*(Q14+R14)/2/Inputs!$C$21*(1+Inputs!$C$20) -> 1006.5 | V14: =IF(E14="40HC",ROUNDUP(C14/VLOOKUP(B14,Inputs!$A$54:$L$60,12,0),0)*VLOOKUP(D14,Inputs!$A$36:$B$38,2,TRUE()),0) -> 0 | W14: =Inputs!$C$22 -> 1025 | X14: =I14+S14+U14+V14+W14 -> 122728.52 | Y14: =X14/C14 -> 24545.704 | Z14: =VLOOKUP(D14,Inputs!$A$66:$B$85,2,TRUE()) -> 90.96 | AA14: =Y14/Z14 -> 269.85163 | AB14: =SUMIFS('Data - SAP Issues'!$N$4:$N$254,'Data - SAP Issues'!$K$4:$K$254,A14) -> 87.374595
A15: J/25-26/151 | B15: 2000 | C15: 5 | D15: 46100 | E15: =VLOOKUP(B15,Inputs!$A$54:$L$60,11,0) -> 40HC | F15: =SUMIFS('Data - SAP Issues'!$I$4:$I$254,'Data - SAP Issues'!$K$4:$K$254,A15,'Data - SAP Issues'!$M$4:$M$254,"Timber") -> 25212.1 | G15: =SUMIFS('Data - SAP Issues'!$I$4:$I$254,'Data - SAP Issues'!$K$4:$K$254,A15)-F15 -> 23123.8 | H15: 0 | I15: =F15+G15-H15 -> 48335.9 | J15: =SUMIFS('Data - Labour'!$M$5:$M$92,'Data - Labour'!$G$5:$G$92,A15,'Data - Labour'!$B$5:$B$92,"Mistri") -> 20 | K15: =SUMIFS('Data - Labour'!$M$5:$M$92,'Data - Labour'!$G$5:$G$92,A15,'Data - Labour'!$B$5:$B$92,"Jogali") -> 46 | L15: =IF(J15+K15>0,"Yes","No") -> Yes | M15: =IF(L15="Yes",J15/C15,"") -> 4 | N15: =IF(L15="Yes",K15/C15,"") -> 9.2 | O15: =IF(L15="Yes",J15,AVERAGEIFS($M$5:$M$23,$B$5:$B$23,B15)*C15) -> 20 | P15: =IF(L15="Yes",K15,AVERAGEIFS($N$5:$N$23,$B$5:$B$23,B15)*C15) -> 46 | Q15: =VLOOKUP(D15,Inputs!$A$30:$C$32,2,TRUE()) -> 760 | R15: =VLOOKUP(D15,Inputs!$A$30:$C$32,3,TRUE()) -> 460 | S15: =(O15*Q15+P15*R15)/Inputs!$C$21*(1+Inputs!$C$20) -> 4999.5 | T15: =SUMIFS('Data - Labour'!$N$5:$N$92,'Data - Labour'!$G$5:$G$92,A15) -> 6 | U15: =T15*(Q15+R15)/2/Inputs!$C$21*(1+Inputs!$C$20) -> 503.25 | V15: =IF(E15="40HC",ROUNDUP(C15/VLOOKUP(B15,Inputs!$A$54:$L$60,12,0),0)*VLOOKUP(D15,Inputs!$A$36:$B$38,2,TRUE()),0) -> 6400 | W15: =Inputs!$C$22 -> 1025 | X15: =I15+S15+U15+V15+W15 -> 61263.65 | Y15: =X15/C15 -> 12252.73 | Z15: =VLOOKUP(D15,Inputs!$A$66:$B$85,2,TRUE()) -> 92.63 | AA15: =Y15/Z15 -> 132.27604 | AB15: =SUMIFS('Data - SAP Issues'!$N$4:$N$254,'Data - SAP Issues'!$K$4:$K$254,A15) -> 35.012072 | AC15: released BOM (first packing BOM)
A16: J/25-26/152 | B16: 1400 | C16: 3 | D16: 46107 | E16: =VLOOKUP(B16,Inputs!$A$54:$L$60,11,0) -> 40HC | F16: =SUMIFS('Data - SAP Issues'!$I$4:$I$254,'Data - SAP Issues'!$K$4:$K$254,A16,'Data - SAP Issues'!$M$4:$M$254,"Timber") -> 13057.37 | G16: =SUMIFS('Data - SAP Issues'!$I$4:$I$254,'Data - SAP Issues'!$K$4:$K$254,A16)-F16 -> 16324.4 | H16: 680 | I16: =F16+G16-H16 -> 28701.77 | J16: =SUMIFS('Data - Labour'!$M$5:$M$92,'Data - Labour'!$G$5:$G$92,A16,'Data - Labour'!$B$5:$B$92,"Mistri") -> 10.5 | K16: =SUMIFS('Data - Labour'!$M$5:$M$92,'Data - Labour'!$G$5:$G$92,A16,'Data - Labour'!$B$5:$B$92,"Jogali") -> 26.5 | L16: =IF(J16+K16>0,"Yes","No") -> Yes | M16: =IF(L16="Yes",J16/C16,"") -> 3.5 | N16: =IF(L16="Yes",K16/C16,"") -> 8.8333333 | O16: =IF(L16="Yes",J16,AVERAGEIFS($M$5:$M$23,$B$5:$B$23,B16)*C16) -> 10.5 | P16: =IF(L16="Yes",K16,AVERAGEIFS($N$5:$N$23,$B$5:$B$23,B16)*C16) -> 26.5 | Q16: =VLOOKUP(D16,Inputs!$A$30:$C$32,2,TRUE()) -> 760 | R16: =VLOOKUP(D16,Inputs!$A$30:$C$32,3,TRUE()) -> 460 | S16: =(O16*Q16+P16*R16)/Inputs!$C$21*(1+Inputs!$C$20) -> 2773.375 | T16: =SUMIFS('Data - Labour'!$N$5:$N$92,'Data - Labour'!$G$5:$G$92,A16) -> 3 | U16: =T16*(Q16+R16)/2/Inputs!$C$21*(1+Inputs!$C$20) -> 251.625 | V16: =IF(E16="40HC",ROUNDUP(C16/VLOOKUP(B16,Inputs!$A$54:$L$60,12,0),0)*VLOOKUP(D16,Inputs!$A$36:$B$38,2,TRUE()),0) -> 3200 | W16: =Inputs!$C$22 -> 1025 | X16: =I16+S16+U16+V16+W16 -> 35951.77 | Y16: =X16/C16 -> 11983.923 | Z16: =VLOOKUP(D16,Inputs!$A$66:$B$85,2,TRUE()) -> 92.63 | AA16: =Y16/Z16 -> 129.3741 | AB16: =SUMIFS('Data - SAP Issues'!$N$4:$N$254,'Data - SAP Issues'!$K$4:$K$254,A16) -> 17.597621 | AC16: 1 day hrs not noted - 8 hrs taken
A17: J/25-26/156 | B17: 1800 | C17: 3 | D17: 46121 | E17: =VLOOKUP(B17,Inputs!$A$54:$L$60,11,0) -> 40HC | F17: =SUMIFS('Data - SAP Issues'!$I$4:$I$254,'Data - SAP Issues'!$K$4:$K$254,A17,'Data - SAP Issues'!$M$4:$M$254,"Timber") -> 17332.95 | G17: =SUMIFS('Data - SAP Issues'!$I$4:$I$254,'Data - SAP Issues'!$K$4:$K$254,A17)-F17 -> 16857 | H17: 0 | I17: =F17+G17-H17 -> 34189.95 | J17: =SUMIFS('Data - Labour'!$M$5:$M$92,'Data - Labour'!$G$5:$G$92,A17,'Data - Labour'!$B$5:$B$92,"Mistri") -> 12 | K17: =SUMIFS('Data - Labour'!$M$5:$M$92,'Data - Labour'!$G$5:$G$92,A17,'Data - Labour'!$B$5:$B$92,"Jogali") -> 30 | L17: =IF(J17+K17>0,"Yes","No") -> Yes | M17: =IF(L17="Yes",J17/C17,"") -> 4 | N17: =IF(L17="Yes",K17/C17,"") -> 10 | O17: =IF(L17="Yes",J17,AVERAGEIFS($M$5:$M$23,$B$5:$B$23,B17)*C17) -> 12 | P17: =IF(L17="Yes",K17,AVERAGEIFS($N$5:$N$23,$B$5:$B$23,B17)*C17) -> 30 | Q17: =VLOOKUP(D17,Inputs!$A$30:$C$32,2,TRUE()) -> 800 | R17: =VLOOKUP(D17,Inputs!$A$30:$C$32,3,TRUE()) -> 460 | S17: =(O17*Q17+P17*R17)/Inputs!$C$21*(1+Inputs!$C$20) -> 3217.5 | T17: =SUMIFS('Data - Labour'!$N$5:$N$92,'Data - Labour'!$G$5:$G$92,A17) -> 2 | U17: =T17*(Q17+R17)/2/Inputs!$C$21*(1+Inputs!$C$20) -> 173.25 | V17: =IF(E17="40HC",ROUNDUP(C17/VLOOKUP(B17,Inputs!$A$54:$L$60,12,0),0)*VLOOKUP(D17,Inputs!$A$36:$B$38,2,TRUE()),0) -> 3200 | W17: =Inputs!$C$22 -> 1025 | X17: =I17+S17+U17+V17+W17 -> 41805.7 | Y17: =X17/C17 -> 13935.233 | Z17: =VLOOKUP(D17,Inputs!$A$66:$B$85,2,TRUE()) -> 92.63 | AA17: =Y17/Z17 -> 150.43974 | AB17: =SUMIFS('Data - SAP Issues'!$N$4:$N$254,'Data - SAP Issues'!$K$4:$K$254,A17) -> 23.359772
A18: J/25-26/137 | B18: 3000 | C18: 3 | D18: 46129 | E18: =VLOOKUP(B18,Inputs!$A$54:$L$60,11,0) -> Flat rack | F18: =SUMIFS('Data - SAP Issues'!$I$4:$I$254,'Data - SAP Issues'!$K$4:$K$254,A18,'Data - SAP Issues'!$M$4:$M$254,"Timber") -> 36922.31 | G18: =SUMIFS('Data - SAP Issues'!$I$4:$I$254,'Data - SAP Issues'!$K$4:$K$254,A18)-F18 -> 46991.8 | H18: 0 | I18: =F18+G18-H18 -> 83914.11 | J18: =SUMIFS('Data - Labour'!$M$5:$M$92,'Data - Labour'!$G$5:$G$92,A18,'Data - Labour'!$B$5:$B$92,"Mistri") -> 32 | K18: =SUMIFS('Data - Labour'!$M$5:$M$92,'Data - Labour'!$G$5:$G$92,A18,'Data - Labour'!$B$5:$B$92,"Jogali") -> 72 | L18: =IF(J18+K18>0,"Yes","No") -> Yes | M18: =IF(L18="Yes",J18/C18,"") -> 10.666667 | N18: =IF(L18="Yes",K18/C18,"") -> 24 | O18: =IF(L18="Yes",J18,AVERAGEIFS($M$5:$M$23,$B$5:$B$23,B18)*C18) -> 32 | P18: =IF(L18="Yes",K18,AVERAGEIFS($N$5:$N$23,$B$5:$B$23,B18)*C18) -> 72 | Q18: =VLOOKUP(D18,Inputs!$A$30:$C$32,2,TRUE()) -> 800 | R18: =VLOOKUP(D18,Inputs!$A$30:$C$32,3,TRUE()) -> 460 | S18: =(O18*Q18+P18*R18)/Inputs!$C$21*(1+Inputs!$C$20) -> 8074 | T18: =SUMIFS('Data - Labour'!$N$5:$N$92,'Data - Labour'!$G$5:$G$92,A18) -> 9.5 | U18: =T18*(Q18+R18)/2/Inputs!$C$21*(1+Inputs!$C$20) -> 822.9375 | V18: =IF(E18="40HC",ROUNDUP(C18/VLOOKUP(B18,Inputs!$A$54:$L$60,12,0),0)*VLOOKUP(D18,Inputs!$A$36:$B$38,2,TRUE()),0) -> 0 | W18: =Inputs!$C$22 -> 1025 | X18: =I18+S18+U18+V18+W18 -> 93836.048 | Y18: =X18/C18 -> 31278.682 | Z18: =VLOOKUP(D18,Inputs!$A$66:$B$85,2,TRUE()) -> 93.54 | AA18: =Y18/Z18 -> 334.38831 | AB18: =SUMIFS('Data - SAP Issues'!$N$4:$N$254,'Data - SAP Issues'!$K$4:$K$254,A18) -> 50.288061 | AC18: 1 + 2 nos, 2 dispatches
A19: J/25-26/158 | B19: 2600 | C19: 4 | D19: 46135 | E19: =VLOOKUP(B19,Inputs!$A$54:$L$60,11,0) -> Flat rack | F19: =SUMIFS('Data - SAP Issues'!$I$4:$I$254,'Data - SAP Issues'!$K$4:$K$254,A19,'Data - SAP Issues'!$M$4:$M$254,"Timber") -> 53105.65 | G19: =SUMIFS('Data - SAP Issues'!$I$4:$I$254,'Data - SAP Issues'!$K$4:$K$254,A19)-F19 -> 50509.4 | H19: 0 | I19: =F19+G19-H19 -> 103615.05 | J19: =SUMIFS('Data - Labour'!$M$5:$M$92,'Data - Labour'!$G$5:$G$92,A19,'Data - Labour'!$B$5:$B$92,"Mistri") -> 31 | K19: =SUMIFS('Data - Labour'!$M$5:$M$92,'Data - Labour'!$G$5:$G$92,A19,'Data - Labour'!$B$5:$B$92,"Jogali") -> 69.5 | L19: =IF(J19+K19>0,"Yes","No") -> Yes | M19: =IF(L19="Yes",J19/C19,"") -> 7.75 | N19: =IF(L19="Yes",K19/C19,"") -> 17.375 | O19: =IF(L19="Yes",J19,AVERAGEIFS($M$5:$M$23,$B$5:$B$23,B19)*C19) -> 31 | P19: =IF(L19="Yes",K19,AVERAGEIFS($N$5:$N$23,$B$5:$B$23,B19)*C19) -> 69.5 | Q19: =VLOOKUP(D19,Inputs!$A$30:$C$32,2,TRUE()) -> 800 | R19: =VLOOKUP(D19,Inputs!$A$30:$C$32,3,TRUE()) -> 460 | S19: =(O19*Q19+P19*R19)/Inputs!$C$21*(1+Inputs!$C$20) -> 7805.875 | T19: =SUMIFS('Data - Labour'!$N$5:$N$92,'Data - Labour'!$G$5:$G$92,A19) -> 7.5 | U19: =T19*(Q19+R19)/2/Inputs!$C$21*(1+Inputs!$C$20) -> 649.6875 | V19: =IF(E19="40HC",ROUNDUP(C19/VLOOKUP(B19,Inputs!$A$54:$L$60,12,0),0)*VLOOKUP(D19,Inputs!$A$36:$B$38,2,TRUE()),0) -> 0 | W19: =Inputs!$C$22 -> 1025 | X19: =I19+S19+U19+V19+W19 -> 113095.61 | Y19: =X19/C19 -> 28273.903 | Z19: =VLOOKUP(D19,Inputs!$A$66:$B$85,2,TRUE()) -> 93.16 | AA19: =Y19/Z19 -> 303.49832 | AB19: =SUMIFS('Data - SAP Issues'!$N$4:$N$254,'Data - SAP Issues'!$K$4:$K$254,A19) -> 71.571163
A20: J/25-26/164 | B20: 2400 | C20: 3 | D20: 46156 | E20: =VLOOKUP(B20,Inputs!$A$54:$L$60,11,0) -> Flat rack | F20: =SUMIFS('Data - SAP Issues'!$I$4:$I$254,'Data - SAP Issues'!$K$4:$K$254,A20,'Data - SAP Issues'!$M$4:$M$254,"Timber") -> 30942.14 | G20: =SUMIFS('Data - SAP Issues'!$I$4:$I$254,'Data - SAP Issues'!$K$4:$K$254,A20)-F20 -> 34937.8 | H20: 0 | I20: =F20+G20-H20 -> 65879.94 | J20: =SUMIFS('Data - Labour'!$M$5:$M$92,'Data - Labour'!$G$5:$G$92,A20,'Data - Labour'!$B$5:$B$92,"Mistri") -> 31 | K20: =SUMIFS('Data - Labour'!$M$5:$M$92,'Data - Labour'!$G$5:$G$92,A20,'Data - Labour'!$B$5:$B$92,"Jogali") -> 58.5 | L20: =IF(J20+K20>0,"Yes","No") -> Yes | M20: =IF(L20="Yes",J20/C20,"") -> 10.333333 | N20: =IF(L20="Yes",K20/C20,"") -> 19.5 | O20: =IF(L20="Yes",J20,AVERAGEIFS($M$5:$M$23,$B$5:$B$23,B20)*C20) -> 31 | P20: =IF(L20="Yes",K20,AVERAGEIFS($N$5:$N$23,$B$5:$B$23,B20)*C20) -> 58.5 | Q20: =VLOOKUP(D20,Inputs!$A$30:$C$32,2,TRUE()) -> 800 | R20: =VLOOKUP(D20,Inputs!$A$30:$C$32,3,TRUE()) -> 460 | S20: =(O20*Q20+P20*R20)/Inputs!$C$21*(1+Inputs!$C$20) -> 7110.125 | T20: =SUMIFS('Data - Labour'!$N$5:$N$92,'Data - Labour'!$G$5:$G$92,A20) -> 8.5 | U20: =T20*(Q20+R20)/2/Inputs!$C$21*(1+Inputs!$C$20) -> 736.3125 | V20: =IF(E20="40HC",ROUNDUP(C20/VLOOKUP(B20,Inputs!$A$54:$L$60,12,0),0)*VLOOKUP(D20,Inputs!$A$36:$B$38,2,TRUE()),0) -> 0 | W20: =Inputs!$C$22 -> 1025 | X20: =I20+S20+U20+V20+W20 -> 74751.378 | Y20: =X20/C20 -> 24917.126 | Z20: =VLOOKUP(D20,Inputs!$A$66:$B$85,2,TRUE()) -> 95.11 | AA20: =Y20/Z20 -> 261.98219 | AB20: =SUMIFS('Data - SAP Issues'!$N$4:$N$254,'Data - SAP Issues'!$K$4:$K$254,A20) -> 41.70111
A21: J/25-26/165 | B21: 1600 | C21: 1 | D21: 46177 | E21: =VLOOKUP(B21,Inputs!$A$54:$L$60,11,0) -> 40HC | F21: =SUMIFS('Data - SAP Issues'!$I$4:$I$254,'Data - SAP Issues'!$K$4:$K$254,A21,'Data - SAP Issues'!$M$4:$M$254,"Timber") -> 5747.64 | G21: =SUMIFS('Data - SAP Issues'!$I$4:$I$254,'Data - SAP Issues'!$K$4:$K$254,A21)-F21 -> 7262.4 | H21: 0 | I21: =F21+G21-H21 -> 13010.04 | J21: =SUMIFS('Data - Labour'!$M$5:$M$92,'Data - Labour'!$G$5:$G$92,A21,'Data - Labour'!$B$5:$B$92,"Mistri") -> 5 | K21: =SUMIFS('Data - Labour'!$M$5:$M$92,'Data - Labour'!$G$5:$G$92,A21,'Data - Labour'!$B$5:$B$92,"Jogali") -> 10 | L21: =IF(J21+K21>0,"Yes","No") -> Yes | M21: =IF(L21="Yes",J21/C21,"") -> 5 | N21: =IF(L21="Yes",K21/C21,"") -> 10 | O21: =IF(L21="Yes",J21,AVERAGEIFS($M$5:$M$23,$B$5:$B$23,B21)*C21) -> 5 | P21: =IF(L21="Yes",K21,AVERAGEIFS($N$5:$N$23,$B$5:$B$23,B21)*C21) -> 10 | Q21: =VLOOKUP(D21,Inputs!$A$30:$C$32,2,TRUE()) -> 800 | R21: =VLOOKUP(D21,Inputs!$A$30:$C$32,3,TRUE()) -> 460 | S21: =(O21*Q21+P21*R21)/Inputs!$C$21*(1+Inputs!$C$20) -> 1182.5 | T21: =SUMIFS('Data - Labour'!$N$5:$N$92,'Data - Labour'!$G$5:$G$92,A21) -> 0 | U21: =T21*(Q21+R21)/2/Inputs!$C$21*(1+Inputs!$C$20) -> 0 | V21: =IF(E21="40HC",ROUNDUP(C21/VLOOKUP(B21,Inputs!$A$54:$L$60,12,0),0)*VLOOKUP(D21,Inputs!$A$36:$B$38,2,TRUE()),0) -> 3200 | W21: =Inputs!$C$22 -> 1025 | X21: =I21+S21+U21+V21+W21 -> 18417.54 | Y21: =X21/C21 -> 18417.54 | Z21: =VLOOKUP(D21,Inputs!$A$66:$B$85,2,TRUE()) -> 96.18 | AA21: =Y21/Z21 -> 191.49033 | AB21: =SUMIFS('Data - SAP Issues'!$N$4:$N$254,'Data - SAP Issues'!$K$4:$K$254,A21) -> 7.7461313 | AC21: 2 lines posted to wrong job in SAP - corrected
A22: J/25-26/167 | B22: 2600 | C22: 3 | D22: 46191 | E22: =VLOOKUP(B22,Inputs!$A$54:$L$60,11,0) -> Flat rack | F22: =SUMIFS('Data - SAP Issues'!$I$4:$I$254,'Data - SAP Issues'!$K$4:$K$254,A22,'Data - SAP Issues'!$M$4:$M$254,"Timber") -> 36018.81 | G22: =SUMIFS('Data - SAP Issues'!$I$4:$I$254,'Data - SAP Issues'!$K$4:$K$254,A22)-F22 -> 41721 | H22: 0 | I22: =F22+G22-H22 -> 77739.81 | J22: =SUMIFS('Data - Labour'!$M$5:$M$92,'Data - Labour'!$G$5:$G$92,A22,'Data - Labour'!$B$5:$B$92,"Mistri") -> 30 | K22: =SUMIFS('Data - Labour'!$M$5:$M$92,'Data - Labour'!$G$5:$G$92,A22,'Data - Labour'!$B$5:$B$92,"Jogali") -> 71 | L22: =IF(J22+K22>0,"Yes","No") -> Yes | M22: =IF(L22="Yes",J22/C22,"") -> 10 | N22: =IF(L22="Yes",K22/C22,"") -> 23.666667 | O22: =IF(L22="Yes",J22,AVERAGEIFS($M$5:$M$23,$B$5:$B$23,B22)*C22) -> 30 | P22: =IF(L22="Yes",K22,AVERAGEIFS($N$5:$N$23,$B$5:$B$23,B22)*C22) -> 71 | Q22: =VLOOKUP(D22,Inputs!$A$30:$C$32,2,TRUE()) -> 800 | R22: =VLOOKUP(D22,Inputs!$A$30:$C$32,3,TRUE()) -> 460 | S22: =(O22*Q22+P22*R22)/Inputs!$C$21*(1+Inputs!$C$20) -> 7790.75 | T22: =SUMIFS('Data - Labour'!$N$5:$N$92,'Data - Labour'!$G$5:$G$92,A22) -> 10.5 | U22: =T22*(Q22+R22)/2/Inputs!$C$21*(1+Inputs!$C$20) -> 909.5625 | V22: =IF(E22="40HC",ROUNDUP(C22/VLOOKUP(B22,Inputs!$A$54:$L$60,12,0),0)*VLOOKUP(D22,Inputs!$A$36:$B$38,2,TRUE()),0) -> 0 | W22: =Inputs!$C$22 -> 1025 | X22: =I22+S22+U22+V22+W22 -> 87465.122 | Y22: =X22/C22 -> 29155.041 | Z22: =VLOOKUP(D22,Inputs!$A$66:$B$85,2,TRUE()) -> 96.18 | AA22: =Y22/Z22 -> 303.12997 | AB22: =SUMIFS('Data - SAP Issues'!$N$4:$N$254,'Data - SAP Issues'!$K$4:$K$254,A22) -> 47.077058
A23: J/26-27/018 | B23: 2000 | C23: 6 | D23: 46226 | E23: =VLOOKUP(B23,Inputs!$A$54:$L$60,11,0) -> 40HC | F23: =SUMIFS('Data - SAP Issues'!$I$4:$I$254,'Data - SAP Issues'!$K$4:$K$254,A23,'Data - SAP Issues'!$M$4:$M$254,"Timber") -> 31436.16 | G23: =SUMIFS('Data - SAP Issues'!$I$4:$I$254,'Data - SAP Issues'!$K$4:$K$254,A23)-F23 -> 25593.2 | H23: 0 | I23: =F23+G23-H23 -> 57029.36 | J23: =SUMIFS('Data - Labour'!$M$5:$M$92,'Data - Labour'!$G$5:$G$92,A23,'Data - Labour'!$B$5:$B$92,"Mistri") -> 21 | K23: =SUMIFS('Data - Labour'!$M$5:$M$92,'Data - Labour'!$G$5:$G$92,A23,'Data - Labour'!$B$5:$B$92,"Jogali") -> 59 | L23: =IF(J23+K23>0,"Yes","No") -> Yes | M23: =IF(L23="Yes",J23/C23,"") -> 3.5 | N23: =IF(L23="Yes",K23/C23,"") -> 9.8333333 | O23: =IF(L23="Yes",J23,AVERAGEIFS($M$5:$M$23,$B$5:$B$23,B23)*C23) -> 21 | P23: =IF(L23="Yes",K23,AVERAGEIFS($N$5:$N$23,$B$5:$B$23,B23)*C23) -> 59 | Q23: =VLOOKUP(D23,Inputs!$A$30:$C$32,2,TRUE()) -> 800 | R23: =VLOOKUP(D23,Inputs!$A$30:$C$32,3,TRUE()) -> 480 | S23: =(O23*Q23+P23*R23)/Inputs!$C$21*(1+Inputs!$C$20) -> 6204 | T23: =SUMIFS('Data - Labour'!$N$5:$N$92,'Data - Labour'!$G$5:$G$92,A23) -> 7.5 | U23: =T23*(Q23+R23)/2/Inputs!$C$21*(1+Inputs!$C$20) -> 660 | V23: =IF(E23="40HC",ROUNDUP(C23/VLOOKUP(B23,Inputs!$A$54:$L$60,12,0),0)*VLOOKUP(D23,Inputs!$A$36:$B$38,2,TRUE()),0) -> 7000 | W23: =Inputs!$C$22 -> 1025 | X23: =I23+S23+U23+V23+W23 -> 71918.36 | Y23: =X23/C23 -> 11986.393 | Z23: =VLOOKUP(D23,Inputs!$A$66:$B$85,2,TRUE()) -> 95.38 | AA23: =Y23/Z23 -> 125.66988 | AB23: =SUMIFS('Data - SAP Issues'!$N$4:$N$254,'Data - SAP Issues'!$K$4:$K$254,A23) -> 41.087599 | AC23: released BOM (first packing BOM)
A25: TOTAL | C25: =SUM(C5:C23) -> 60 | F25: =SUM(F5:F23) -> 507035.87 | G25: =SUM(G5:G23) -> 501051 | H25: =SUM(H5:H23) -> 1808.8 | I25: =SUM(I5:I23) -> 1006278.1 | S25: =SUM(S5:S23) -> 98191.305 | U25: =SUM(U5:U23) -> 5797 | V25: =SUM(V5:V23) -> 41400 | W25: =SUM(W5:W23) -> 19475 | X25: =SUM(X5:X23) -> 1171141.4 | Y25: =X25/C25 -> 19519.023 | AB25: =SUM(AB5:AB23) -> 699.51758
A27: OT is paid at double rate, so OT hours add one extra ordinary rate (average of carpenter and helper). Fumigation = containers x rate for 40HC jobs.

Sheet Proposed Std
A1: Proposed packing standard per vessel - worked out from past jobs
A2: No BOM existed except for 2.0 m. Average used per vessel by size = the proposed standard, to be signed off by production.
A4: Size (mm) | B4: UoM | C4: 1400 | D4: 1600 | E4: 1800 | F4: 2000 | G4: 2400 | H4: 2600 | I4: 3000
A5: Jobs packed | C5: =COUNTIF('Job Costing'!$B$5:$B$23,C$4) -> 2 | D5: =COUNTIF('Job Costing'!$B$5:$B$23,D$4) -> 2 | E5: =COUNTIF('Job Costing'!$B$5:$B$23,E$4) -> 3 | F5: =COUNTIF('Job Costing'!$B$5:$B$23,F$4) -> 3 | G5: =COUNTIF('Job Costing'!$B$5:$B$23,G$4) -> 4 | H5: =COUNTIF('Job Costing'!$B$5:$B$23,H$4) -> 4 | I5: =COUNTIF('Job Costing'!$B$5:$B$23,I$4) -> 1
A6: Vessels packed | C6: =SUMIFS('Job Costing'!$C$5:$C$23,'Job Costing'!$B$5:$B$23,C$4) -> 5 | D6: =SUMIFS('Job Costing'!$C$5:$C$23,'Job Costing'!$B$5:$B$23,D$4) -> 3 | E6: =SUMIFS('Job Costing'!$C$5:$C$23,'Job Costing'!$B$5:$B$23,E$4) -> 9 | F6: =SUMIFS('Job Costing'!$C$5:$C$23,'Job Costing'!$B$5:$B$23,F$4) -> 14 | G6: =SUMIFS('Job Costing'!$C$5:$C$23,'Job Costing'!$B$5:$B$23,G$4) -> 14 | H6: =SUMIFS('Job Costing'!$C$5:$C$23,'Job Costing'!$B$5:$B$23,H$4) -> 12 | I6: =SUMIFS('Job Costing'!$C$5:$C$23,'Job Costing'!$B$5:$B$23,I$4) -> 3
A8: A. Average used per vessel (SAP issues / vessels)
A9: Timber | B9: cft | C9: =SUMIFS('Data - SAP Issues'!$N$4:$N$254,'Data - SAP Issues'!$L$4:$L$254,C$4)/C$6 -> 7.0747999 | D9: =SUMIFS('Data - SAP Issues'!$N$4:$N$254,'Data - SAP Issues'!$L$4:$L$254,D$4)/D$6 -> 8.1610238 | E9: =SUMIFS('Data - SAP Issues'!$N$4:$N$254,'Data - SAP Issues'!$L$4:$L$254,E$4)/E$6 -> 7.649274 | F9: =SUMIFS('Data - SAP Issues'!$N$4:$N$254,'Data - SAP Issues'!$L$4:$L$254,F$4)/F$6 -> 7.2539981 | G9: =SUMIFS('Data - SAP Issues'!$N$4:$N$254,'Data - SAP Issues'!$L$4:$L$254,G$4)/G$6 -> 15.595513 | H9: =SUMIFS('Data - SAP Issues'!$N$4:$N$254,'Data - SAP Issues'!$L$4:$L$254,H$4)/H$6 -> 16.719653 | I9: =SUMIFS('Data - SAP Issues'!$N$4:$N$254,'Data - SAP Issues'!$L$4:$L$254,I$4)/I$6 -> 16.762687 | K9: includes spares and splits seen in the issues
A10: Nails | B10: set | C10: =SUMIFS('Data - SAP Issues'!$F$4:$F$254,'Data - SAP Issues'!$L$4:$L$254,C$4,'Data - SAP Issues'!$M$4:$M$254,$A10)/C$6 -> 1.2 | D10: =SUMIFS('Data - SAP Issues'!$F$4:$F$254,'Data - SAP Issues'!$L$4:$L$254,D$4,'Data - SAP Issues'!$M$4:$M$254,$A10)/D$6 -> 1.6666667 | E10: =SUMIFS('Data - SAP Issues'!$F$4:$F$254,'Data - SAP Issues'!$L$4:$L$254,E$4,'Data - SAP Issues'!$M$4:$M$254,$A10)/E$6 -> 1.3333333 | F10: =SUMIFS('Data - SAP Issues'!$F$4:$F$254,'Data - SAP Issues'!$L$4:$L$254,F$4,'Data - SAP Issues'!$M$4:$M$254,$A10)/F$6 -> 1.0714286 | G10: =SUMIFS('Data - SAP Issues'!$F$4:$F$254,'Data - SAP Issues'!$L$4:$L$254,G$4,'Data - SAP Issues'!$M$4:$M$254,$A10)/G$6 -> 2.4285714 | H10: =SUMIFS('Data - SAP Issues'!$F$4:$F$254,'Data - SAP Issues'!$L$4:$L$254,H$4,'Data - SAP Issues'!$M$4:$M$254,$A10)/H$6 -> 2.3333333 | I10: =SUMIFS('Data - SAP Issues'!$F$4:$F$254,'Data - SAP Issues'!$L$4:$L$254,I$4,'Data - SAP Issues'!$M$4:$M$254,$A10)/I$6 -> 3
A11: Foam | B11: roll | C11: =SUMIFS('Data - SAP Issues'!$F$4:$F$254,'Data - SAP Issues'!$L$4:$L$254,C$4,'Data - SAP Issues'!$M$4:$M$254,$A11)/C$6 -> 0.6 | D11: =SUMIFS('Data - SAP Issues'!$F$4:$F$254,'Data - SAP Issues'!$L$4:$L$254,D$4,'Data - SAP Issues'!$M$4:$M$254,$A11)/D$6 -> 0.66666667 | E11: =SUMIFS('Data - SAP Issues'!$F$4:$F$254,'Data - SAP Issues'!$L$4:$L$254,E$4,'Data - SAP Issues'!$M$4:$M$254,$A11)/E$6 -> 0.55555556 | F11: =SUMIFS('Data - SAP Issues'!$F$4:$F$254,'Data - SAP Issues'!$L$4:$L$254,F$4,'Data - SAP Issues'!$M$4:$M$254,$A11)/F$6 -> 0.57142857 | G11: =SUMIFS('Data - SAP Issues'!$F$4:$F$254,'Data - SAP Issues'!$L$4:$L$254,G$4,'Data - SAP Issues'!$M$4:$M$254,$A11)/G$6 -> 1 | H11: =SUMIFS('Data - SAP Issues'!$F$4:$F$254,'Data - SAP Issues'!$L$4:$L$254,H$4,'Data - SAP Issues'!$M$4:$M$254,$A11)/H$6 -> 1.1666667 | I11: =SUMIFS('Data - SAP Issues'!$F$4:$F$254,'Data - SAP Issues'!$L$4:$L$254,I$4,'Data - SAP Issues'!$M$4:$M$254,$A11)/I$6 -> 1.3333333
A12: Ratchet belt | B12: nos | C12: =SUMIFS('Data - SAP Issues'!$F$4:$F$254,'Data - SAP Issues'!$L$4:$L$254,C$4,'Data - SAP Issues'!$M$4:$M$254,$A12)/C$6 -> 2.2 | D12: =SUMIFS('Data - SAP Issues'!$F$4:$F$254,'Data - SAP Issues'!$L$4:$L$254,D$4,'Data - SAP Issues'!$M$4:$M$254,$A12)/D$6 -> 2.3333333 | E12: =SUMIFS('Data - SAP Issues'!$F$4:$F$254,'Data - SAP Issues'!$L$4:$L$254,E$4,'Data - SAP Issues'!$M$4:$M$254,$A12)/E$6 -> 2.1111111 | F12: =SUMIFS('Data - SAP Issues'!$F$4:$F$254,'Data - SAP Issues'!$L$4:$L$254,F$4,'Data - SAP Issues'!$M$4:$M$254,$A12)/F$6 -> 2.2857143 | G12: =SUMIFS('Data - SAP Issues'!$F$4:$F$254,'Data - SAP Issues'!$L$4:$L$254,G$4,'Data - SAP Issues'!$M$4:$M$254,$A12)/G$6 -> 3.0714286 | H12: =SUMIFS('Data - SAP Issues'!$F$4:$F$254,'Data - SAP Issues'!$L$4:$L$254,H$4,'Data - SAP Issues'!$M$4:$M$254,$A12)/H$6 -> 3.5 | I12: =SUMIFS('Data - SAP Issues'!$F$4:$F$254,'Data - SAP Issues'!$L$4:$L$254,I$4,'Data - SAP Issues'!$M$4:$M$254,$A12)/I$6 -> 4
A13: Gum tape | B13: roll | C13: =SUMIFS('Data - SAP Issues'!$F$4:$F$254,'Data - SAP Issues'!$L$4:$L$254,C$4,'Data - SAP Issues'!$M$4:$M$254,$A13)/C$6 -> 0.8 | D13: =SUMIFS('Data - SAP Issues'!$F$4:$F$254,'Data - SAP Issues'!$L$4:$L$254,D$4,'Data - SAP Issues'!$M$4:$M$254,$A13)/D$6 -> 1 | E13: =SUMIFS('Data - SAP Issues'!$F$4:$F$254,'Data - SAP Issues'!$L$4:$L$254,E$4,'Data - SAP Issues'!$M$4:$M$254,$A13)/E$6 -> 1 | F13: =SUMIFS('Data - SAP Issues'!$F$4:$F$254,'Data - SAP Issues'!$L$4:$L$254,F$4,'Data - SAP Issues'!$M$4:$M$254,$A13)/F$6 -> 1 | G13: =SUMIFS('Data - SAP Issues'!$F$4:$F$254,'Data - SAP Issues'!$L$4:$L$254,G$4,'Data - SAP Issues'!$M$4:$M$254,$A13)/G$6 -> 1.6428571 | H13: =SUMIFS('Data - SAP Issues'!$F$4:$F$254,'Data - SAP Issues'!$L$4:$L$254,H$4,'Data - SAP Issues'!$M$4:$M$254,$A13)/H$6 -> 1.9166667 | I13: =SUMIFS('Data - SAP Issues'!$F$4:$F$254,'Data - SAP Issues'!$L$4:$L$254,I$4,'Data - SAP Issues'!$M$4:$M$254,$A13)/I$6 -> 2.3333333
A14: Stretch film | B14: kg | C14: =SUMIFS('Data - SAP Issues'!$F$4:$F$254,'Data - SAP Issues'!$L$4:$L$254,C$4,'Data - SAP Issues'!$M$4:$M$254,$A14)/C$6 -> 2.16 | D14: =SUMIFS('Data - SAP Issues'!$F$4:$F$254,'Data - SAP Issues'!$L$4:$L$254,D$4,'Data - SAP Issues'!$M$4:$M$254,$A14)/D$6 -> 3.5 | E14: =SUMIFS('Data - SAP Issues'!$F$4:$F$254,'Data - SAP Issues'!$L$4:$L$254,E$4,'Data - SAP Issues'!$M$4:$M$254,$A14)/E$6 -> 3.5222222 | F14: =SUMIFS('Data - SAP Issues'!$F$4:$F$254,'Data - SAP Issues'!$L$4:$L$254,F$4,'Data - SAP Issues'!$M$4:$M$254,$A14)/F$6 -> 2.7571429 | G14: =SUMIFS('Data - SAP Issues'!$F$4:$F$254,'Data - SAP Issues'!$L$4:$L$254,G$4,'Data - SAP Issues'!$M$4:$M$254,$A14)/G$6 -> 4.5714286 | H14: =SUMIFS('Data - SAP Issues'!$F$4:$F$254,'Data - SAP Issues'!$L$4:$L$254,H$4,'Data - SAP Issues'!$M$4:$M$254,$A14)/H$6 -> 5.2833333 | I14: =SUMIFS('Data - SAP Issues'!$F$4:$F$254,'Data - SAP Issues'!$L$4:$L$254,I$4,'Data - SAP Issues'!$M$4:$M$254,$A14)/I$6 -> 7.1
A15: Bubble wrap | B15: roll | C15: =SUMIFS('Data - SAP Issues'!$F$4:$F$254,'Data - SAP Issues'!$L$4:$L$254,C$4,'Data - SAP Issues'!$M$4:$M$254,$A15)/C$6 -> 0.8 | D15: =SUMIFS('Data - SAP Issues'!$F$4:$F$254,'Data - SAP Issues'!$L$4:$L$254,D$4,'Data - SAP Issues'!$M$4:$M$254,$A15)/D$6 -> 1 | E15: =SUMIFS('Data - SAP Issues'!$F$4:$F$254,'Data - SAP Issues'!$L$4:$L$254,E$4,'Data - SAP Issues'!$M$4:$M$254,$A15)/E$6 -> 0.88888889 | F15: =SUMIFS('Data - SAP Issues'!$F$4:$F$254,'Data - SAP Issues'!$L$4:$L$254,F$4,'Data - SAP Issues'!$M$4:$M$254,$A15)/F$6 -> 0.92857143 | G15: =SUMIFS('Data - SAP Issues'!$F$4:$F$254,'Data - SAP Issues'!$L$4:$L$254,G$4,'Data - SAP Issues'!$M$4:$M$254,$A15)/G$6 -> 1.6428571 | H15: =SUMIFS('Data - SAP Issues'!$F$4:$F$254,'Data - SAP Issues'!$L$4:$L$254,H$4,'Data - SAP Issues'!$M$4:$M$254,$A15)/H$6 -> 1.75 | I15: =SUMIFS('Data - SAP Issues'!$F$4:$F$254,'Data - SAP Issues'!$L$4:$L$254,I$4,'Data - SAP Issues'!$M$4:$M$254,$A15)/I$6 -> 3 | K15: 2.0 m: BOM quantity + 1 roll re-wrap after rain
A16: Ply cover | B16: nos | C16: =SUMIFS('Data - SAP Issues'!$F$4:$F$254,'Data - SAP Issues'!$L$4:$L$254,C$4,'Data - SAP Issues'!$M$4:$M$254,$A16)/C$6 -> 5.4 | D16: =SUMIFS('Data - SAP Issues'!$F$4:$F$254,'Data - SAP Issues'!$L$4:$L$254,D$4,'Data - SAP Issues'!$M$4:$M$254,$A16)/D$6 -> 5 | E16: =SUMIFS('Data - SAP Issues'!$F$4:$F$254,'Data - SAP Issues'!$L$4:$L$254,E$4,'Data - SAP Issues'!$M$4:$M$254,$A16)/E$6 -> 5.3333333 | F16: =SUMIFS('Data - SAP Issues'!$F$4:$F$254,'Data - SAP Issues'!$L$4:$L$254,F$4,'Data - SAP Issues'!$M$4:$M$254,$A16)/F$6 -> 0 | G16: =SUMIFS('Data - SAP Issues'!$F$4:$F$254,'Data - SAP Issues'!$L$4:$L$254,G$4,'Data - SAP Issues'!$M$4:$M$254,$A16)/G$6 -> 5.5714286 | H16: =SUMIFS('Data - SAP Issues'!$F$4:$F$254,'Data - SAP Issues'!$L$4:$L$254,H$4,'Data - SAP Issues'!$M$4:$M$254,$A16)/H$6 -> 5.5 | I16: =SUMIFS('Data - SAP Issues'!$F$4:$F$254,'Data - SAP Issues'!$L$4:$L$254,I$4,'Data - SAP Issues'!$M$4:$M$254,$A16)/I$6 -> 5
A17: Tarpaulin | B17: sqft | C17: =SUMIFS('Data - SAP Issues'!$F$4:$F$254,'Data - SAP Issues'!$L$4:$L$254,C$4,'Data - SAP Issues'!$M$4:$M$254,$A17)/C$6 -> 0 | D17: =SUMIFS('Data - SAP Issues'!$F$4:$F$254,'Data - SAP Issues'!$L$4:$L$254,D$4,'Data - SAP Issues'!$M$4:$M$254,$A17)/D$6 -> 0 | E17: =SUMIFS('Data - SAP Issues'!$F$4:$F$254,'Data - SAP Issues'!$L$4:$L$254,E$4,'Data - SAP Issues'!$M$4:$M$254,$A17)/E$6 -> 0 | F17: =SUMIFS('Data - SAP Issues'!$F$4:$F$254,'Data - SAP Issues'!$L$4:$L$254,F$4,'Data - SAP Issues'!$M$4:$M$254,$A17)/F$6 -> 0 | G17: =SUMIFS('Data - SAP Issues'!$F$4:$F$254,'Data - SAP Issues'!$L$4:$L$254,G$4,'Data - SAP Issues'!$M$4:$M$254,$A17)/G$6 -> 542.85714 | H17: =SUMIFS('Data - SAP Issues'!$F$4:$F$254,'Data - SAP Issues'!$L$4:$L$254,H$4,'Data - SAP Issues'!$M$4:$M$254,$A17)/H$6 -> 741.66667 | I17: =SUMIFS('Data - SAP Issues'!$F$4:$F$254,'Data - SAP Issues'!$L$4:$L$254,I$4,'Data - SAP Issues'!$M$4:$M$254,$A17)/I$6 -> 966.66667
A19: B. Standard cost per vessel at current rates (₹)
A20: Timber | C20: =C9*VLOOKUP($A20,Inputs!$A$6:$C$17,3,0) -> 5518.3439 | D20: =D9*VLOOKUP($A20,Inputs!$A$6:$C$17,3,0) -> 6365.5985 | E20: =E9*VLOOKUP($A20,Inputs!$A$6:$C$17,3,0) -> 5966.4337 | F20: =F9*VLOOKUP($A20,Inputs!$A$6:$C$17,3,0) -> 5658.1185 | G20: =G9*VLOOKUP($A20,Inputs!$A$6:$C$17,3,0) -> 12164.5 | H20: =H9*VLOOKUP($A20,Inputs!$A$6:$C$17,3,0) -> 13041.329 | I20: =I9*VLOOKUP($A20,Inputs!$A$6:$C$17,3,0) -> 13074.896
A21: Nails | C21: =C10*VLOOKUP($A21,Inputs!$A$6:$C$17,3,0) -> 118.8 | D21: =D10*VLOOKUP($A21,Inputs!$A$6:$C$17,3,0) -> 165 | E21: =E10*VLOOKUP($A21,Inputs!$A$6:$C$17,3,0) -> 132 | F21: =F10*VLOOKUP($A21,Inputs!$A$6:$C$17,3,0) -> 106.07143 | G21: =G10*VLOOKUP($A21,Inputs!$A$6:$C$17,3,0) -> 240.42857 | H21: =H10*VLOOKUP($A21,Inputs!$A$6:$C$17,3,0) -> 231 | I21: =I10*VLOOKUP($A21,Inputs!$A$6:$C$17,3,0) -> 297
A22: Foam | C22: =C11*VLOOKUP($A22,Inputs!$A$6:$C$17,3,0) -> 1350 | D22: =D11*VLOOKUP($A22,Inputs!$A$6:$C$17,3,0) -> 1500 | E22: =E11*VLOOKUP($A22,Inputs!$A$6:$C$17,3,0) -> 1250 | F22: =F11*VLOOKUP($A22,Inputs!$A$6:$C$17,3,0) -> 1285.7143 | G22: =G11*VLOOKUP($A22,Inputs!$A$6:$C$17,3,0) -> 2250 | H22: =H11*VLOOKUP($A22,Inputs!$A$6:$C$17,3,0) -> 2625 | I22: =I11*VLOOKUP($A22,Inputs!$A$6:$C$17,3,0) -> 3000
A23: Ratchet belt | C23: =C12*VLOOKUP($A23,Inputs!$A$6:$C$17,3,0) -> 2090 | D23: =D12*VLOOKUP($A23,Inputs!$A$6:$C$17,3,0) -> 2216.6667 | E23: =E12*VLOOKUP($A23,Inputs!$A$6:$C$17,3,0) -> 2005.5556 | F23: =F12*VLOOKUP($A23,Inputs!$A$6:$C$17,3,0) -> 2171.4286 | G23: =G12*VLOOKUP($A23,Inputs!$A$6:$C$17,3,0) -> 2917.8571 | H23: =H12*VLOOKUP($A23,Inputs!$A$6:$C$17,3,0) -> 3325 | I23: =I12*VLOOKUP($A23,Inputs!$A$6:$C$17,3,0) -> 3800
A24: Gum tape | C24: =C13*VLOOKUP($A24,Inputs!$A$6:$C$17,3,0) -> 67.2 | D24: =D13*VLOOKUP($A24,Inputs!$A$6:$C$17,3,0) -> 84 | E24: =E13*VLOOKUP($A24,Inputs!$A$6:$C$17,3,0) -> 84 | F24: =F13*VLOOKUP($A24,Inputs!$A$6:$C$17,3,0) -> 84 | G24: =G13*VLOOKUP($A24,Inputs!$A$6:$C$17,3,0) -> 138 | H24: =H13*VLOOKUP($A24,Inputs!$A$6:$C$17,3,0) -> 161 | I24: =I13*VLOOKUP($A24,Inputs!$A$6:$C$17,3,0) -> 196
A25: Stretch film | C25: =C14*VLOOKUP($A25,Inputs!$A$6:$C$17,3,0) -> 362.44068 | D25: =D14*VLOOKUP($A25,Inputs!$A$6:$C$17,3,0) -> 587.28814 | E25: =E14*VLOOKUP($A25,Inputs!$A$6:$C$17,3,0) -> 591.01695 | F25: =F14*VLOOKUP($A25,Inputs!$A$6:$C$17,3,0) -> 462.63923 | G25: =G14*VLOOKUP($A25,Inputs!$A$6:$C$17,3,0) -> 767.07022 | H25: =H14*VLOOKUP($A25,Inputs!$A$6:$C$17,3,0) -> 886.52542 | I25: =I14*VLOOKUP($A25,Inputs!$A$6:$C$17,3,0) -> 1191.3559
A26: Bubble wrap | C26: =C15*VLOOKUP($A26,Inputs!$A$6:$C$17,3,0) -> 568 | D26: =D15*VLOOKUP($A26,Inputs!$A$6:$C$17,3,0) -> 710 | E26: =E15*VLOOKUP($A26,Inputs!$A$6:$C$17,3,0) -> 631.11111 | F26: =F15*VLOOKUP($A26,Inputs!$A$6:$C$17,3,0) -> 659.28571 | G26: =G15*VLOOKUP($A26,Inputs!$A$6:$C$17,3,0) -> 1166.4286 | H26: =H15*VLOOKUP($A26,Inputs!$A$6:$C$17,3,0) -> 1242.5 | I26: =I15*VLOOKUP($A26,Inputs!$A$6:$C$17,3,0) -> 2130
A27: Ply cover | C27: =C16*VLOOKUP($A27,Inputs!$A$6:$C$17,3,0) -> 864 | D27: =D16*VLOOKUP($A27,Inputs!$A$6:$C$17,3,0) -> 800 | E27: =E16*VLOOKUP($A27,Inputs!$A$6:$C$17,3,0) -> 853.33333 | F27: =F16*VLOOKUP($A27,Inputs!$A$6:$C$17,3,0) -> 0 | G27: =G16*VLOOKUP($A27,Inputs!$A$6:$C$17,3,0) -> 891.42857 | H27: =H16*VLOOKUP($A27,Inputs!$A$6:$C$17,3,0) -> 880 | I27: =I16*VLOOKUP($A27,Inputs!$A$6:$C$17,3,0) -> 800
A28: Tarpaulin | C28: =C17*VLOOKUP($A28,Inputs!$A$6:$C$17,3,0) -> 0 | D28: =D17*VLOOKUP($A28,Inputs!$A$6:$C$17,3,0) -> 0 | E28: =E17*VLOOKUP($A28,Inputs!$A$6:$C$17,3,0) -> 0 | F28: =F17*VLOOKUP($A28,Inputs!$A$6:$C$17,3,0) -> 0 | G28: =G17*VLOOKUP($A28,Inputs!$A$6:$C$17,3,0) -> 2714.2857 | H28: =H17*VLOOKUP($A28,Inputs!$A$6:$C$17,3,0) -> 3708.3333 | I28: =I17*VLOOKUP($A28,Inputs!$A$6:$C$17,3,0) -> 4833.3333
A29: Material cost per vessel | C29: =SUM(C20:C28) -> 10938.785 | D29: =SUM(D20:D28) -> 12428.553 | E29: =SUM(E20:E28) -> 11513.451 | F29: =SUM(F20:F28) -> 10427.258 | G29: =SUM(G20:G28) -> 23249.999 | H29: =SUM(H20:H28) -> 26100.688 | I29: =SUM(I20:I28) -> 29322.585
A31: C. Actual vs design BOM - 2.0 m (the one size with a BOM; earlier jobs were packed before it existed)
A32: Item | B32: UoM | C32: Released BOM | D32: Average used | E32: Difference
A33: Timber | B33: cft | C33: =SUM('Data - 2.0m BOM'!H4:H14) -> 6.8479331 | D33: =F9 -> 7.2539981 | E33: =D33-C33 -> 0.406065
A34: Nails | B34: set | C34: ='Data - 2.0m BOM'!D9 -> 1 | D34: =F10 -> 1.0714286 | E34: =D34-C34 -> 0.071428571
A35: Foam | B35: roll | C35: ='Data - 2.0m BOM'!D10 -> 0.5 | D35: =F11 -> 0.57142857 | E35: =D35-C35 -> 0.071428571
A36: Ratchet belt | B36: nos | C36: ='Data - 2.0m BOM'!D11 -> 2 | D36: =F12 -> 2.2857143 | E36: =D36-C36 -> 0.28571429
A37: Gum tape | B37: roll | C37: ='Data - 2.0m BOM'!D12 -> 0.833 | D37: =F13 -> 1 | E37: =D37-C37 -> 0.167
A38: Stretch film | B38: kg | C38: ='Data - 2.0m BOM'!D13 -> 2.333 | D38: =F14 -> 2.7571429 | E38: =D38-C38 -> 0.42414286
A39: Bubble wrap | B39: roll | C39: ='Data - 2.0m BOM'!D14 -> 0.833 | D39: =F15 -> 0.92857143 | E39: =D39-C39 -> 0.095571429
A41: D. Draft BOM for release - timber pieces per vessel, by size
A42: Item | B42: Size (mm) | C42: Avg pieces / vsl | D42: Proposed pieces / vsl
A43: WOODEN BATTEN 100 X 100 X 900 LG | B43: 1400 | C43: =SUMIFS('Data - SAP Issues'!$F$4:$F$254,'Data - SAP Issues'!$L$4:$L$254,B43,'Data - SAP Issues'!$E$4:$E$254,A43)/SUMIFS('Job Costing'!$C$5:$C$23,'Job Costing'!$B$5:$B$23,B43) -> 5 | D43: =ROUND(C43,0) -> 5
A44: WOODEN BATTEN 100 X 75 X 100 LG | B44: 1400 | C44: =SUMIFS('Data - SAP Issues'!$F$4:$F$254,'Data - SAP Issues'!$L$4:$L$254,B44,'Data - SAP Issues'!$E$4:$E$254,A44)/SUMIFS('Job Costing'!$C$5:$C$23,'Job Costing'!$B$5:$B$23,B44) -> 4.2 | D44: =ROUND(C44,0) -> 4
A45: WOODEN BATTEN 150 X 150 X 300 LG | B45: 1400 | C45: =SUMIFS('Data - SAP Issues'!$F$4:$F$254,'Data - SAP Issues'!$L$4:$L$254,B45,'Data - SAP Issues'!$E$4:$E$254,A45)/SUMIFS('Job Costing'!$C$5:$C$23,'Job Costing'!$B$5:$B$23,B45) -> 4.2 | D45: =ROUND(C45,0) -> 4
...

Sheet Size Model
A1: Size model - in-house vs outsourcing, per vessel at current rates
A2: Vessels per shipment from the Dashboard. Proposed standard from 'Proposed Std'.
A4: Size (mm) | C4: 1400 | D4: 1600 | E4: 1800 | F4: 2000 | G4: 2400 | H4: 2600 | I4: 3000
A5: Ship mode | C5: =VLOOKUP(C$4,Inputs!$A$54:$L$60,11,0) -> 40HC | D5: =VLOOKUP(D$4,Inputs!$A$54:$L$60,11,0) -> 40HC | E5: =VLOOKUP(E$4,Inputs!$A$54:$L$60,11,0) -> 40HC | F5: =VLOOKUP(F$4,Inputs!$A$54:$L$60,11,0) -> 40HC | G5: =VLOOKUP(G$4,Inputs!$A$54:$L$60,11,0) -> Flat rack | H5: =VLOOKUP(H$4,Inputs!$A$54:$L$60,11,0) -> Flat rack | I5: =VLOOKUP(I$4,Inputs!$A$54:$L$60,11,0) -> Flat rack
A6: Vessels per 40HC container | C6: =VLOOKUP(C$4,Inputs!$A$54:$L$60,12,0) -> 3 | D6: =VLOOKUP(D$4,Inputs!$A$54:$L$60,12,0) -> 3 | E6: =VLOOKUP(E$4,Inputs!$A$54:$L$60,12,0) -> 3 | F6: =VLOOKUP(F$4,Inputs!$A$54:$L$60,12,0) -> 3 | G6: =VLOOKUP(G$4,Inputs!$A$54:$L$60,12,0) -> - | H6: =VLOOKUP(H$4,Inputs!$A$54:$L$60,12,0) -> - | I6: =VLOOKUP(I$4,Inputs!$A$54:$L$60,12,0) -> -
A7: Per vessel - proposed standard, current rates
A8: Timber ₹ | C8: ='Proposed Std'!C20 -> 5518.3439 | D8: ='Proposed Std'!D20 -> 6365.5985 | E8: ='Proposed Std'!E20 -> 5966.4337 | F8: ='Proposed Std'!F20 -> 5658.1185 | G8: ='Proposed Std'!G20 -> 12164.5 | H8: ='Proposed Std'!H20 -> 13041.329 | I8: ='Proposed Std'!I20 -> 13074.896
A9: Consumables ₹ | C9: ='Proposed Std'!C29-'Proposed Std'!C20 -> 5420.4407 | D9: ='Proposed Std'!D29-'Proposed Std'!D20 -> 6062.9548 | E9: ='Proposed Std'!E29-'Proposed Std'!E20 -> 5547.0169 | F9: ='Proposed Std'!F29-'Proposed Std'!F20 -> 4769.1392 | G9: ='Proposed Std'!G29-'Proposed Std'!G20 -> 11085.499 | H9: ='Proposed Std'!H29-'Proposed Std'!H20 -> 13059.359 | I9: ='Proposed Std'!I29-'Proposed Std'!I20 -> 16247.689
A10: of which nails ₹ | C10: ='Proposed Std'!C21 -> 118.8 | D10: ='Proposed Std'!D21 -> 165 | E10: ='Proposed Std'!E21 -> 132 | F10: ='Proposed Std'!F21 -> 106.07143 | G10: ='Proposed Std'!G21 -> 240.42857 | H10: ='Proposed Std'!H21 -> 231 | I10: ='Proposed Std'!I21 -> 297
A11: Material ₹ | C11: =C8+C9 -> 10938.785 | D11: =D8+D9 -> 12428.553 | E11: =E8+E9 -> 11513.451 | F11: =F8+F9 -> 10427.258 | G11: =G8+G9 -> 23249.999 | H11: =H8+H9 -> 26100.688 | I11: =I8+I9 -> 29322.585
A12: Mistri hrs per vessel | C12: =AVERAGEIFS('Job Costing'!$M$5:$M$23,'Job Costing'!$B$5:$B$23,C$4) -> 3.5 | D12: =AVERAGEIFS('Job Costing'!$M$5:$M$23,'Job Costing'!$B$5:$B$23,D$4) -> 4.625 | E12: =AVERAGEIFS('Job Costing'!$M$5:$M$23,'Job Costing'!$B$5:$B$23,E$4) -> 4.75 | F12: =AVERAGEIFS('Job Costing'!$M$5:$M$23,'Job Costing'!$B$5:$B$23,F$4) -> 3.75 | G12: =AVERAGEIFS('Job Costing'!$M$5:$M$23,'Job Costing'!$B$5:$B$23,G$4) -> 9.8166667 | H12: =AVERAGEIFS('Job Costing'!$M$5:$M$23,'Job Costing'!$B$5:$B$23,H$4) -> 8.875 | I12: =AVERAGEIFS('Job Costing'!$M$5:$M$23,'Job Costing'!$B$5:$B$23,I$4) -> 10.666667 | K12: average of jobs with a labour record
A13: Jogali hrs per vessel | C13: =AVERAGEIFS('Job Costing'!$N$5:$N$23,'Job Costing'!$B$5:$B$23,C$4) -> 8.8333333 | D13: =AVERAGEIFS('Job Costing'!$N$5:$N$23,'Job Costing'!$B$5:$B$23,D$4) -> 9.625 | E13: =AVERAGEIFS('Job Costing'!$N$5:$N$23,'Job Costing'!$B$5:$B$23,E$4) -> 10.125 | F13: =AVERAGEIFS('Job Costing'!$N$5:$N$23,'Job Costing'!$B$5:$B$23,F$4) -> 9.5166667 | G13: =AVERAGEIFS('Job Costing'!$N$5:$N$23,'Job Costing'!$B$5:$B$23,G$4) -> 18.95 | H13: =AVERAGEIFS('Job Costing'!$N$5:$N$23,'Job Costing'!$B$5:$B$23,H$4) -> 20.520833 | I13: =AVERAGEIFS('Job Costing'!$N$5:$N$23,'Job Costing'!$B$5:$B$23,I$4) -> 24
